<?xml version="1.0"?>
<robot name="C:/Users/rares/OneDrive/Desktop/Robot.urdf" xmlns:xacro="http://ros.org/wiki/xacro">
  <link name="base_link">
    <visual>
      <origin xyz="0 0 0.0415" rpy="0 0 -1.570796"/>
      <geometry>
        <cylinder radius="0.045" length="0.08"/>
      </geometry>
    </visual>
    <collision>
      <origin xyz="0 0 0.0415" rpy="0 0 -1.570796"/>
      <geometry>
        <cylinder radius="0.045" length="0.08"/>
      </geometry>
    </collision>
  </link>
  <link name="camera">
  </link>
  <joint name="base_link_camera_joint" type="fixed">
    <parent link="base_link"/>
    <child link="camera"/>
    <origin xyz="0.04 0 0.0915" rpy="-1.570796 0 -1.570796"/>
  </joint>
  <link name="ds1">
  </link>
  <joint name="base_link_ds1_joint" type="fixed">
    <parent link="base_link"/>
    <child link="ds1"/>
    <origin xyz="0.042 -0.02 0.063" rpy="0 0 -0.500795"/>
  </joint>
  <link name="ds0">
  </link>
  <joint name="base_link_ds0_joint" type="fixed">
    <parent link="base_link"/>
    <child link="ds0"/>
    <origin xyz="0.042 0.02 0.063" rpy="0 0 0.499205"/>
  </joint>
  <joint name="right wheel motor" type="continuous">
    <parent link="base_link"/>
    <child link="right wheel"/>
    <axis xyz="-1 0 0"/>
    <limit effort="10" velocity="10"/>
    <origin xyz="0 0 0.025" rpy="-0.125039 0 -1.570796"/>
  </joint>
  <link name="right wheel">
    <visual>
      <origin xyz="0.045 0 0" rpy="-1.570796 0 1.57"/>
      <geometry>
        <cylinder radius="0.025" length="0.01"/>
      </geometry>
    </visual>
    <collision>
      <origin xyz="0.045 0 0" rpy="-1.570796 0 1.57"/>
      <geometry>
        <cylinder radius="0.025" length="0.01"/>
      </geometry>
    </collision>
  </link>
  <joint name="left wheel motor" type="continuous">
    <parent link="base_link"/>
    <child link="left wheel"/>
    <axis xyz="-1 0 0"/>
    <limit effort="10" velocity="10"/>
    <origin xyz="0.045 0 0.025" rpy="0.27228 0 -1.570796"/>
  </joint>
  <link name="left wheel">
    <visual>
      <origin xyz="-0.045 0 0" rpy="-1.570796 0 1.57"/>
      <geometry>
        <cylinder radius="0.025" length="0.01"/>
      </geometry>
    </visual>
    <collision>
      <origin xyz="-0.045 0 0" rpy="-1.570796 0 1.57"/>
      <geometry>
        <cylinder radius="0.025" length="0.01"/>
      </geometry>
    </collision>
  </link>
</robot>
